<?xml version="1.0" encoding="UTF-8"?>
<!-- Generated by org.testng.reporters.JUnitXMLReporter -->
<testsuite ignored="0" hostname="LaShawn" failures="2" tests="14" name="firefoxTest" time="125.895" errors="0" timestamp="2025-08-28T11:52:39 EDT">
  <testcase classname="testCases.TC01_LaunchApplication" name="testLaunchApplication" time="0.064"/>
  <testcase classname="testCases.TC03_AddToCart" name="testAddToCart" time="7.926"/>
  <testcase classname="testCases.TC05_AddToWishList" name="testAddToWishList" time="3.513">
    <skipped/>
  </testcase> <!-- testAddToWishList -->
  <testcase classname="testCases.TC05_AddToWishList" name="testAddToWishList" time="10.113">
    <skipped/>
  </testcase> <!-- testAddToWishList -->
  <testcase classname="testCases.TC05_AddToWishList" name="testAddToWishList" time="10.128">
    <failure type="java.lang.AssertionError" message="Test failed due to unexpected exception.">
      <![CDATA[java.lang.AssertionError: Test failed due to unexpected exception.
at testCases.TC05_AddToWishList.testAddToWishList(TC05_AddToWishList.java:68)
at java.base/java.util.ArrayList.forEach(ArrayList.java:1597)
at java.base/java.util.concurrent.FutureTask.run(FutureTask.java:317)
at java.base/java.util.concurrent.ThreadPoolExecutor.runWorker(ThreadPoolExecutor.java:1144)
at java.base/java.util.concurrent.ThreadPoolExecutor$Worker.run(ThreadPoolExecutor.java:642)
at java.base/java.lang.Thread.run(Thread.java:1575)
... Removed 16 stack frames]]>
    </failure>
  </testcase> <!-- testAddToWishList -->
  <testcase classname="testCases.TC06_AddAffiliate" name="testAddAffiliate" time="3.977"/>
  <testcase classname="testCases.TC02_Login" name="testLogin" time="1.703"/>
  <testcase classname="testCases.TC02_Login" name="testLogin" time="1.185"/>
  <testcase classname="testCases.TC02_Login" name="testLogin" time="1.449"/>
  <testcase classname="testCases.TC02_Login" name="testLogin" time="1.876"/>
  <testcase classname="testCases.TC02_Login" name="testLogin" time="1.729"/>
  <testcase classname="testCases.TC04_CompletePurchase" name="testCompletePurchase" time="6.241">
    <skipped/>
  </testcase> <!-- testCompletePurchase -->
  <testcase classname="testCases.TC04_CompletePurchase" name="testCompletePurchase" time="0.547">
    <skipped/>
  </testcase> <!-- testCompletePurchase -->
  <testcase classname="testCases.TC04_CompletePurchase" name="testCompletePurchase" time="0.531">
    <failure type="java.lang.AssertionError" message="Test failed due to unexpected exception.">
      <![CDATA[java.lang.AssertionError: Test failed due to unexpected exception.
at testCases.TC04_CompletePurchase.testCompletePurchase(TC04_CompletePurchase.java:81)
at java.base/java.util.ArrayList.forEach(ArrayList.java:1597)
at java.base/java.util.concurrent.FutureTask.run(FutureTask.java:317)
at java.base/java.util.concurrent.ThreadPoolExecutor.runWorker(ThreadPoolExecutor.java:1144)
at java.base/java.util.concurrent.ThreadPoolExecutor$Worker.run(ThreadPoolExecutor.java:642)
at java.base/java.lang.Thread.run(Thread.java:1575)
... Removed 16 stack frames]]>
    </failure>
  </testcase> <!-- testCompletePurchase -->
</testsuite> <!-- firefoxTest -->
